# 为什么要写异常？

要知道c语音是没有这种java的异常体系的，但c语言任何软件都可以写出来

```java
boolean register(string username,string pwd){
    
}
```

上面的设计，任何注册不成功的情况，都只能返回false，调用者就不知道真正的原因。有时是需要知道真正的原因，那么方法的设计就必须更改

```java
int register(string username,string pwd){
    
}
```

这种设计之后，就人为编制一份文档，记录各个不同返回值的含义，比如1表示成功，100表示用户名被占用了，101表示密码不符合规范

这种可以解决问题，但缺陷是代码与文档要同步维护，通常会出现不一致的情况，还有一种就是代码不直观，不容易理解

```java
if (result == 100){
    alert('用户名已经被使用了');
}else if(result == 102){
    alert('密码');
}
```

所以后面编程语言就改变了这种数字型的处理逻辑，改成类型化的处理逻辑

```java
boolean register(string username,string pwd){
   ...
    throw new UserExistExeption();
    ...
    throw new PasswordIsInvalid();
}
```

上面写法时既能通过逻辑判断出注册是否成功，也可以通过抛出异常让调用者知道出错的原因，之后调用者就可以处理

```java
try{
    register()
}catch(UserExistException uee){
    alert('换一个名字')
}catch(PaswordIsInvalid pii){
    alert('换密码')
}
```

# 怎么抛？

在方法里面用throw来抛异常

```java
throw new XxxException();
```

throw语句后面的代码（逻辑上）不会执行，方法提前结束了

# 抛什么异常呢？

能抛的异常，一般就是jdk提供的或者你使用的某些框架里的异常，比如spring提供，如果没有现成合适的异常，你就需要自己编写异常类，比如UserExistException（用户已经存在的）

java的异常分为两类，一个是Error，一个是Exception，Exception继续分为两类，一个是运行时异常，一个是检查异常

- Error异常一般是虚拟机出现，我们程序员基本不会使用，表示错误，出现了你也解决不了，等着重启程序或者只能等死。比如出现内存不足这种错误

- 编译异常也叫（检查异常，也叫checked异常）



![exception_leibie](images/exception_leibie.png)

# 运行时异常与检查异常

​	如果方法内部抛出的是一个RuntimeException，那么方法的签名是不需要throws语句的，比如下面

```java
   public void m1(){
        throw new ArithmeticException("算术运算出错");
    }
```

​	运行时异常特点：方法内部随便抛，方法签名上可以没有throws，调用此方法时也不需要去理会

如果抛出的是一个检查异常，比如

```java
 public void m2(){
        throw new FileNotFoundException("文件找不到");
    }
```

检查异常就是要在写代码的时候检查，也就是在编译的时候要处理，处理有两种逻辑：要么继续抛出，让别人处理，要么自己处理

比如，下面的就是自己处理掉这个抛出的异常

```java
public void doSth(){
    try {
        throw new FileNotFoundException("文件找不到");
    } catch (FileNotFoundException e) {

    }
}
```

要么就继续抛

```java
  public void doSth() throws FileNotFoundException{
        throw new FileNotFoundException("文件找不到");
    }
```

检查异常特点：内部可能抛了一个检查异常，要么自己处理掉，要么继续抛，继续抛就会改变方法的签名，要有throws

# 自定义异常

自己编写的异常有三个要点

- 名字以Exception结尾
- 父类是RuntimeException
- 类里面的基础代码就是三个构造函数,可以添加其它构造函数，也可以添加其它的属性、方法等，构造函数里的代码通常是调用父类对应签名的构造函数

```java
public class UserExistException extends RuntimeException{
    //下面3个是基础的写法
    //1. 默认构造函数：表示只是有个错误，无特别的信息
    public UserExistException() {
        super();
    }

    //2.一个字符串类型的构造函数，表示有异常的描述信息
    public UserExistException(String message) {
        super(message);
    }

    //3.有异常的描述信息，并且还包括上一个异常信息
    public UserExistException(String message, Throwable cause) {
        super(message, cause);
    }
    //在异常类里面是可以写额外的代码，实际项目中有这种情况

}
```



# 怎么捕获异常

捕获是用catch实现的，一般的做法分为以下情况

- 彻底处理，就不在抛出任何异常，相当于把异常吞掉

```java
public void m2(){
	try{
		m1();

	}catch(A a){
		//处理代码	

	}
}

main(){
    //m2执行中出现了错误，main方法是完全不知道
	m2();
}
```

- 不彻底处理，一般分为处理部分，然后再重抛，重抛的时候就可能抛出异常本身或者抛出一个新的异常

```java
try{
    
}catch(SomeException se){
    //处理代码
    ....
    throw se;
}

//还有一种情况
try{
    
}catch(SomeException se){
    //处理代码
    ....
    throw new OtherException('msg',se);
    //或者像下面这样写
    throw new OtherException('msg');
}
```



捕获是用catch语句来实现，可以有多个catch，是有层次关系的，父类异常出现在后面的catch里，真出了异常，只要找到一个符合的catch就完了

```java
 try {
            new C().m1();
        } catch (ArithmeticException ae) {
            System.out.println("算术出错");
        } catch (IndexOutOfBoundsException iobe) {
            System.out.println("index");
        }catch (RuntimeException re){
            System.out.println("runtime");
        }
```

try块不能单独存在，try必须与catch一起，或与finally一起，或与catch，finally三者一起

一个方法出了异常，调用链上没有任何地方处理，程序就结束，后面的代码不执行，比如下面

```java
new C().m1();
System.out.println("end---");
```

所以，上面的最后一行代码在m1出异常时是不执行，不出异常时是会执行的。所以finally代码块就有意义



# 异常重抛

为了让上层代码知道发生了什么情况，或者是为了换一个其他的异常抛出，比如下面的QueryRunner的insert方法是抛出一个检查异常，这里捕获之后抛出一个运行时异常

```java
private QuerryRunner runner = ....
	
public int insert(){

    try{
        runner.insert()
    }catch(SQLException e){
        throw new RuntimeException("sql执行出错");
    }
}
```

# 异常栈

```java
public class C {

    public void m1() {
      throw new ArithmeticException("算术运算出错");
    }
}

public class B {
    public void m1(){
        C c = new C();
        try {
            c.m1();
        } catch (RuntimeException e) {
            throw new IllegalArgumentException("b--->c(no e) m1 argument");
        }
    }
}

public class A {
    public void m1(){
        C c = new C();
        try {
            c.m1();
        } catch (RuntimeException e) {
            throw new IllegalStateException("a(m1)--->c(with e)  state",e);
        }
    }
}
```



调用B的m1方法时，丢失了异常栈

```java
public class Main {
    public static void main(String[] args) {

        try {
            new B().m1();
        } catch (RuntimeException re) {
            re.printStackTrace();
        }
    }
}
```

输出结果如下

```shell
java.lang.IllegalArgumentException: b--->c(no e) m1 argument
	at com.nf.B.m1(B.java:9)
	at com.nf.Main.main(Main.java:7)
```

调用A的m1方法时，异常栈还在

```java
public class Main {
    public static void main(String[] args) {
        try {
            new A().m1();
        } catch (RuntimeException re) {
            re.printStackTrace();
        }
    }
}
```

输出结果如下

```java
java.lang.IllegalStateException: a(m1)--->c(with e)  state
	at com.nf.A.m1(A.java:9)
	at com.nf.Main.main(Main.java:14)
Caused by: java.lang.ArithmeticException: 算术运算出错
	at com.nf.C.m1(C.java:9)
	at com.nf.A.m1(A.java:7)
	... 1 more
```

# try with resource

jdk7 出现的一个新特性，jdk9进行进一步的增强。比较完善。他的出现是为了解决finally代码块执行的问题

finally代码通常是用来清理资源，而且通常是一定要执行的东西就放在finally块里面的，以前的代码都是类似下面这样

```java
Connection conn = null;
try{
    conn = DriverManager.getConnection();
    ...
}finally{
    if(conn!=null){
        try{
            conn.close();
        }catch(Exception e){
            //彻底处理，比如写点日志
        }
    }
}
```

为了改进上面无聊的写法，就出现了try with resource的写法

```java
//这种写法，自动添加finally代码块，会自动关闭try小括号里面声明的变量，在finally块里面就会调用对象的close方法
try(Connection conn = DriverManager.getConnection()){
    
    ...
}
```

这种写法，有一个要求，就是对象必须实现AutoCloseable接口，注意，此接口有一个子接口叫做Closable，所以很多时候人们都是直接实现Closable接口，有了这个约定，就可以使用try with resource写法

```java
public class MyCloseable implements AutoCloseable{

    public void m1(){
        System.out.println("m1 -***");
        //throw new RuntimeException("m1 in mYClosable");
    }
    @Override
    public void close() throws Exception {
        System.out.println("close-----");
    }
}
//不管m1抛不抛出异常，其close方法都会得到执行
  try(MyCloseable my = new MyCloseable()){
            my.m1();
        }
```

上面的写法，异常是没有处理的，如果你要处理，直接加catch块就可以了，加了catch也仍然有finally块

```java
try (MyCloseable my = new MyCloseable()) {
    my.m1();

} catch (RuntimeException runtimeException) {
    System.out.println("chuli....");
}
```

在try with Resource的写法中，try可以写多个资源声明，用分号分隔，关闭的顺序与声明的顺序是相反的

```java
public class MyCloseable2 implements AutoCloseable{

    public void m1(){
        System.out.println("m1 -2222***");
        throw new RuntimeException("m1 in mYClosable");
    }
    @Override
    public void close() throws Exception {
        System.out.println("close2-----");
    }
}


try (MyCloseable my = new MyCloseable();
            MyCloseable2 my2 = new MyCloseable2()) {
            my2.m1();
            my.m1();

        }


```

输出的结果如下

```shell
m1 -2222***
close2-----
close-----
Exception in thread "main" java.lang.RuntimeException: m1 in mYClosable
	at com.nf.MyCloseable2.m1(MyCloseable2.java:7)
	at com.nf.Main.main(Main.java:24)
```

有时并不能一次性的把所有的资源相关的对象都放在try的小括号里，比如下面的代码是不允许的

```java
  try (MyCloseable my = new MyCloseable();
             String sql="sadfasd";
            MyCloseable2 my2 = new MyCloseable2(sql)) {
         

        }
```

碰到这种情况，就只能采用try with resource的嵌套写法

```java
try (MyCloseable my = new MyCloseable();) {
    
	String sql="sadfasd";
    try(MyCloseable2 my2 = new MyCloseable2(sql)){
        
    }	
}
```



# Java异常最佳实践

 https://cloud.tencent.com/developer/article/1768062  

# 参考资料

https://zhuanlan.zhihu.com/p/27824934（try with resource)

effective java(一本书)

